<?xml version="1.0"?>

<sdf version="1.6">
    <world name="depth_camera_world">
        <!-- sun light -->
        <include>
            <uri>model://sun</uri>
        </include>

        <!-- ground plane -->
        <include>
            <uri>model://ground_plane</uri>
        </include>

        <!-- Some objects to see -->
        <model name="red_box">
            <pose>2 0 0.5 0 0 0</pose>
            <static>true</static>
            <link name="link">
                <collision name="collision">
                    <geometry>
                        <box>
                            <size>1 1 1</size>
                        </box>
                    </geometry>
                </collision>
                <visual name="visual">
                    <geometry>
                        <box>
                            <size>1 1 1</size>
                        </box>
                    </geometry>
                    <material>
                        <ambient>0.8 0.2 0.2 1</ambient>
                        <diffuse>0.8 0.2 0.2 1</diffuse>
                    </material>
                </visual>
            </link>
        </model>
        <model name="green_box">
            <pose>2 1.5 0.25 0 0 0</pose>
            <static>true</static>
            <link name="link">
                <collision name="collision">
                    <geometry>
                        <box>
                            <size>0.5 0.5 0.5</size>
                        </box>
                    </geometry>
                </collision>
                <visual name="visual">
                    <geometry>
                        <box>
                            <size>0.5 0.5 0.5</size>
                        </box>
                    </geometry>
                    <material>
                        <ambient>0.2 0.8 0.2 1</ambient>
                        <diffuse>0.2 0.8 0.2 1</diffuse>
                    </material>
                </visual>
            </link>
        </model>
        <model name="blue_cylinder">
            <pose>2 -1 0.5 0 0 0</pose>
            <static>true</static>
            <link name="link">
                <collision name="collision">
                    <geometry>
                        <cylinder>
                            <radius>0.3</radius>
                            <length>1</length>
                        </cylinder>
                    </geometry>
                </collision>
                <visual name="visual">
                    <geometry>
                        <cylinder>
                            <radius>0.3</radius>
                            <length>1</length>
                        </cylinder>
                    </geometry>
                    <material>
                        <ambient>0.2 0.2 0.8 1</ambient>
                        <diffuse>0.2 0.2 0.8 1</diffuse>
                    </material>
                </visual>
            </link>
        </model>


        <!-- movalbe depth camera robot for point cloud -->
        <model name="camera_robot">
            <pose>0 0 0.1 0 0 0</pose>
            <static>false</static>

            <!-- main body -->
            <link name="base_link">
                <inertial>
                    <mass>5.0</mass>
                    <inertia>
                        <ixx>0.1</ixx>
                        <iyy>0.1</iyy>
                        <izz>0.1</izz>
                    </inertia>
                </inertial>
                <collision name="collision">
                    <pose>0 0 0.05 0 0 0</pose>
                    <geometry>
                        <box>
                            <size>0.3 0.25 0.1</size>
                        </box>
                    </geometry>
                </collision>
                <visual name="visual">
                    <pose>0 0 0.05 0 0 0</pose>
                    <geometry>
                        <box>
                            <size>0.3 0.25 0.1</size>
                        </box>
                    </geometry>
                    <material>
                        <ambient>0.2 0.2 0.2 1</ambient>
                    </material>
                </visual>
                <sensor name="depth_camera" type="depth">
                    <pose>0.15 0 0.1 0 0 0</pose>
                    <update_rate>10</update_rate>
                    <camera>
                        <horizontal_fov>1.047</horizontal_fov>
                        <image>
                            <width>640</width>
                            <height>480</height>
                            <format>R8G8B8</format>
                        </image>
                        <clip>
                            <near>0.1</near>
                            <far>10</far>
                        </clip>
                    </camera>
                    <plugin name="depth_camera_plugin" filename="libgazebo_ros_camera.so">
                        <ros>
                            <namespace>/camera</namespace>
                        </ros>
                        <camera_name>depth</camera_name>
                        <frame_name>camera_depth_optical_frame</frame_name>
                        <hack_baseline>0.07</hack_baseline>
                        <min_depth>0.1</min_depth>
                        <max_depth>10.0</max_depth>
                    </plugin>
                </sensor>
            </link>
            <!-- left wheel -->
            <link name="left_wheel">
                <pose>0 0.15 0.05 -1.5708 0 0</pose>
                <inertial>
                    <mass>0.5</mass>
                    <inertia>
                        <ixx>0.001</ixx>
                        <iyy>0.001</iyy>
                        <izz>0.001</izz>
                    </inertia>
                </inertial>
                <collision name="collision">
                    <geometry>
                        <cylinder>
                            <radius>0.05</radius>
                            <length>0.04</length>
                        </cylinder>
                    </geometry>
                    <surface>
                        <friction>
                            <ode>
                                <mu>1.0</mu>
                                <mu2>1.0</mu2>
                            </ode>
                        </friction>
                    </surface>
                </collision>
                <visual name="visual">
                    <geometry>
                        <cylinder>
                            <radius>0.05</radius>
                            <length>0.04</length>
                        </cylinder>
                    </geometry>
                    <material>
                        <ambient>0.1 0.1 0.1 1</ambient>
                    </material>
                </visual>
            </link>
            <!-- Right wheel -->
            <link name="right_wheel">
                <pose>0 -0.15 0.05 -1.5708 0 0</pose>
                <inertial>
                    <mass>0.5</mass>
                    <inertia>
                        <ixx>0.001</ixx>
                        <iyy>0.001</iyy>
                        <izz>0.001</izz>
                    </inertia>
                </inertial>
                <collision name="collision">
                    <geometry>
                        <cylinder>
                            <radius>0.05</radius>
                            <length>0.04</length>
                        </cylinder>
                    </geometry>
                    <surface>
                        <friction>
                            <ode>
                                <mu>1.0</mu>
                                <mu2>1.0</mu2>
                            </ode>
                        </friction>
                    </surface>
                </collision>
                <visual name="visual">
                    <geometry>
                        <cylinder>
                            <radius>0.05</radius>
                            <length>0.04</length>
                        </cylinder>
                    </geometry>
                    <material>
                        <ambient>0.1 0.1 0.1 1</ambient>
                    </material>
                </visual>
            </link>
            <!-- caster (rear support) -->
            <link name="caster">
                <pose>-0.12 0 0.025 0 0 0</pose>
                <inertial>
                    <mass>0.1</mass>
                    <inertia>
                        <ixx>0.001</ixx>
                        <iyy>0.001</iyy>
                        <izz>0.001</izz>
                    </inertia>
                </inertial>
                <collision name="collision">
                    <geometry>
                        <sphere>
                            <radius>0.025</radius>
                        </sphere>
                    </geometry>
                    <surface>
                        <friction>
                            <ode>
                                <mu>0.0</mu>
                                <mu2>0.0</mu2>
                            </ode>
                        </friction>
                    </surface>
                </collision>
                <visual name="visual">
                    <geometry>
                        <sphere>
                            <radius>0.025</radius>
                        </sphere>
                    </geometry>
                    <material>
                        <ambient>0.3 0.3 0.3 1</ambient>
                    </material>
                </visual>
            </link>

            <!-- joints -->
            <joint name="left_wheel_joint" type="revolute">
                <parent>base_link</parent>
                <child>left_wheel</child>
                <axia>
                    <xyz>0 0 1</xyz>
                </axia>
            </joint>
            <joint name="right_wheel_joint" type="revolute">
                <parent>base_link</parent>
                <child>right_wheel</child>
                <axia>
                    <xyz>0 0 1</xyz>
                </axia>
            </joint>
            <joint name="caster_joint" type="ball">
                <parent>base_link</parent>
                <child>caster</child>
            </joint>
            <plugin name="diff_drive" filename="libgazebo_ros_diff_drive.so">
                <ros>
                    <namespace>/camera_robot</namespace>
                </ros>
                <update_rate>50</update_rate>
                <left_joint>left_wheel_joint</left_joint>
                <right_joint>right_wheel_joint</right_joint>
                <wheel_separation>0.3</wheel_separation>
                <wheel_diameter>0.1</wheel_diameter>
                <max_wheel_torgue>20</max_wheel_torgue>
                <max_wheel_acceleration>1.0</max_wheel_acceleration>
                <command_topic>cmd_vel</command_topic>
                <publish_odom>true</publish_odom>
                <publish_odom_tf>true</publish_odom_tf>
                <odometry_frame>odom</odometry_frame>
                <robot_base_frame>base_link</robot_base_frame>
            </plugin>
        </model>
    </world>
</sdf>
